# 捕获异常

## 异常

```csharp
int i = 0;
Console.WriteLine(0 / i);
```

如果将整数0作为被除数，那么会得到以下输出

```
Unhandled exception. System.DivideByZeroException: Attempted to divide by zero.
   at Program.<Main>$(String[] args) in D:\Csharp12学习笔记\Program.cs:line 3
```

这段输出的意思是

- 未处理的异常
- 异常类型
- 伴随异常传递的消息
- 程序运行的调用栈
- 文件位置和代码位置

这套机制是c#的异常机制。在程序通知用户时，一般只能写一个错误码。

但对于开发人员来说，出现异常时，仍在程序运行阶段，
这个错误在程序内部传递时，可以传递更多的信息而不只是一个错误码。

异常附随一个终止当前方法的作用。并上抛这个异常。
直到有代码捕获这个异常，或是一直上抛到程序入口点导致整个程序终止。

因为异常的本意就是出现了不正常的情况，足以影响到程序的运行，
即便继续下去也会导致非预期的结果产生，所以会中断代码。

## try-catch

使用`try`可以捕获将要发生异常的语句。在`catch`中对异常进行类型判断。
这个过程类似于一个`if-else`的过程，

- 可以无限续接`catch`块。
- 未匹配的`catch`会顺延到下一个`catch`继续判断
- 如果有任何`catch`匹配则不再顺延
- 如果没有任何`catch`匹配则捕获失败，异常继续上抛。
- 最后一个`catch`可以省略条件不再判断类型。

但如果想要将捕获到的异常作为变量对其访问，则必须完整写出异常类型。

```csharp
try
{
 int i = 0;
 Console.WriteLine(0 / i);
}
catch (FileNotFoundException)
{
 Console.WriteLine("捕获到一个异常");
}
catch (IOException e)//将捕获到的异常赋值给变量e
{
 Console.WriteLine(e.Message);
}
catch
{
 Console.WriteLine("未匹配的异常");
}
Console.WriteLine("继续代码");
```

## try-finally

有些代码具有网络连接或其他需要外部资源的操作。
在出现异常后需要关闭这些连接。

使用`try-catch`时，无法确定是否会发生异常。
有可能不会完整运算`try`里的内容，有可能不会运行`catch`里的内容。

而关闭连接是无论执行是否出现异常都要执行的操作。
此时可以在`catch`后附加`finally`块。
在执行完`try`或`catch`后。会执行`finally`块的内容。

`finally`可以在没有`catch`的情况下使用。
但此时可以用不带条件的`catch`替换，

```csharp
try
{
 Console.WriteLine("打开网络连接");
}
catch (HttpIOException)
{
 Console.WriteLine("对方无响应，5秒后重连");
}
catch
{
 Console.WriteLine("未知异常");
}
finally
{
 Console.WriteLine("关闭网络连接");
}
```

## 抛出异常

使用`throw`语句跟随一个异常就可以抛出异常。

在`catch`块中，可以不跟随异常。这样会把捕获到的异常抛出。
捕获但是继续抛出，这个情形一般是记录日志等操作。

```csharp
try
{
 throw new Exception("抛出的异常");
}
catch
{
 throw;
} 
```

## 异常类

异常类是指所有派生自`Exception`的类型。
捕获`Exception`异常和不填写类型是等效的。

你可以自定义派生自`Exception`的异常类。

在不抛出和捕获时，异常实例就是普通的值，可以访问内容，赋值和读取。

## 附加判断

在`try-catch`的`catch`后，可以使用`when`附加一个普通的条件判断。

```csharp
int a = 0, b = 0;
try
{
	Console.WriteLine(a / b);
}
catch (IOException e) when (e.Message.Length < b)
{
}
catch when (a < b)
{
}
catch
{
}
```
